[2022-05-03 12:52:06,934] {taskinstance.py:1043} INFO - Dependencies all met for <TaskInstance: trigger_airbyte_job_example.airbyte_example manual__2022-05-03T12:52:04.994141+00:00 [queued]>
[2022-05-03 12:52:06,937] {taskinstance.py:1043} INFO - Dependencies all met for <TaskInstance: trigger_airbyte_job_example.airbyte_example manual__2022-05-03T12:52:04.994141+00:00 [queued]>
[2022-05-03 12:52:06,937] {taskinstance.py:1249} INFO - 
--------------------------------------------------------------------------------
[2022-05-03 12:52:06,937] {taskinstance.py:1250} INFO - Starting attempt 1 of 1
[2022-05-03 12:52:06,937] {taskinstance.py:1251} INFO - 
--------------------------------------------------------------------------------
[2022-05-03 12:52:06,942] {taskinstance.py:1270} INFO - Executing <Task(AirbyteTriggerSyncOperator): airbyte_example> on 2022-05-03 12:52:04.994141+00:00
[2022-05-03 12:52:06,943] {standard_task_runner.py:52} INFO - Started process 1796 to run task
[2022-05-03 12:52:06,944] {standard_task_runner.py:79} INFO - Running: ['airflow', 'tasks', 'run', 'trigger_airbyte_job_example', 'airbyte_example', 'manual__2022-05-03T12:52:04.994141+00:00', '--job-id', '3', '--raw', '--subdir', 'DAGS_FOLDER/airbyte_trigger_job.py', '--cfg-path', '/tmp/tmpndpsok7v', '--error-file', '/tmp/tmpm4eo_wmc']
[2022-05-03 12:52:06,945] {standard_task_runner.py:80} INFO - Job 3: Subtask airbyte_example
[2022-05-03 12:52:06,958] {logging_mixin.py:109} INFO - Running <TaskInstance: trigger_airbyte_job_example.airbyte_example manual__2022-05-03T12:52:04.994141+00:00 [running]> on host 259f6aa88f20
[2022-05-03 12:52:06,973] {taskinstance.py:1446} INFO - Exporting the following env vars:
AIRFLOW_CTX_DAG_OWNER=airflow
AIRFLOW_CTX_DAG_ID=trigger_airbyte_job_example
AIRFLOW_CTX_TASK_ID=airbyte_example
AIRFLOW_CTX_EXECUTION_DATE=2022-05-03T12:52:04.994141+00:00
AIRFLOW_CTX_DAG_RUN_ID=manual__2022-05-03T12:52:04.994141+00:00
[2022-05-03 12:52:06,975] {base.py:70} INFO - Using connection to: id: airbyte_conn. Host: localhost, Port: 8000, Schema: , Login: , Password: None, extra: {}
[2022-05-03 12:52:06,976] {http.py:129} INFO - Sending 'POST' to url: http://localhost:8000/api/v1/connections/sync
[2022-05-03 12:52:06,977] {http.py:187} WARNING - HTTPConnectionPool(host='localhost', port=8000): Max retries exceeded with url: /api/v1/connections/sync (Caused by NewConnectionError('<urllib3.connection.HTTPConnection object at 0x7fc94a0947f0>: Failed to establish a new connection: [Errno 111] Connection refused')) Tenacity will retry to execute the operation
[2022-05-03 12:52:06,977] {taskinstance.py:1774} ERROR - Task failed with exception
Traceback (most recent call last):
  File "/usr/local/lib/python3.8/site-packages/urllib3/connection.py", line 174, in _new_conn
    conn = connection.create_connection(
  File "/usr/local/lib/python3.8/site-packages/urllib3/util/connection.py", line 95, in create_connection
    raise err
  File "/usr/local/lib/python3.8/site-packages/urllib3/util/connection.py", line 85, in create_connection
    sock.connect(sa)
ConnectionRefusedError: [Errno 111] Connection refused

During handling of the above exception, another exception occurred:

Traceback (most recent call last):
  File "/usr/local/lib/python3.8/site-packages/urllib3/connectionpool.py", line 703, in urlopen
    httplib_response = self._make_request(
  File "/usr/local/lib/python3.8/site-packages/urllib3/connectionpool.py", line 398, in _make_request
    conn.request(method, url, **httplib_request_kw)
  File "/usr/local/lib/python3.8/site-packages/urllib3/connection.py", line 239, in request
    super(HTTPConnection, self).request(method, url, body=body, headers=headers)
  File "/usr/local/lib/python3.8/http/client.py", line 1252, in request
    self._send_request(method, url, body, headers, encode_chunked)
  File "/usr/local/lib/python3.8/http/client.py", line 1298, in _send_request
    self.endheaders(body, encode_chunked=encode_chunked)
  File "/usr/local/lib/python3.8/http/client.py", line 1247, in endheaders
    self._send_output(message_body, encode_chunked=encode_chunked)
  File "/usr/local/lib/python3.8/http/client.py", line 1007, in _send_output
    self.send(msg)
  File "/usr/local/lib/python3.8/http/client.py", line 947, in send
    self.connect()
  File "/usr/local/lib/python3.8/site-packages/urllib3/connection.py", line 205, in connect
    conn = self._new_conn()
  File "/usr/local/lib/python3.8/site-packages/urllib3/connection.py", line 186, in _new_conn
    raise NewConnectionError(
urllib3.exceptions.NewConnectionError: <urllib3.connection.HTTPConnection object at 0x7fc94a0947f0>: Failed to establish a new connection: [Errno 111] Connection refused

During handling of the above exception, another exception occurred:

Traceback (most recent call last):
  File "/usr/local/lib/python3.8/site-packages/requests/adapters.py", line 440, in send
    resp = conn.urlopen(
  File "/usr/local/lib/python3.8/site-packages/urllib3/connectionpool.py", line 785, in urlopen
    retries = retries.increment(
  File "/usr/local/lib/python3.8/site-packages/urllib3/util/retry.py", line 592, in increment
    raise MaxRetryError(_pool, url, error or ResponseError(cause))
urllib3.exceptions.MaxRetryError: HTTPConnectionPool(host='localhost', port=8000): Max retries exceeded with url: /api/v1/connections/sync (Caused by NewConnectionError('<urllib3.connection.HTTPConnection object at 0x7fc94a0947f0>: Failed to establish a new connection: [Errno 111] Connection refused'))

During handling of the above exception, another exception occurred:

Traceback (most recent call last):
  File "/usr/local/lib/python3.8/site-packages/airflow/providers/airbyte/operators/airbyte.py", line 71, in execute
    job_object = hook.submit_sync_connection(connection_id=self.connection_id)
  File "/usr/local/lib/python3.8/site-packages/airflow/providers/airbyte/hooks/airbyte.py", line 92, in submit_sync_connection
    return self.run(
  File "/usr/local/lib/python3.8/site-packages/airflow/providers/http/hooks/http.py", line 130, in run
    return self.run_and_check(session, prepped_request, extra_options)
  File "/usr/local/lib/python3.8/site-packages/airflow/providers/http/hooks/http.py", line 188, in run_and_check
    raise ex
  File "/usr/local/lib/python3.8/site-packages/airflow/providers/http/hooks/http.py", line 180, in run_and_check
    response = session.send(prepped_request, **send_kwargs)
  File "/usr/local/lib/python3.8/site-packages/requests/sessions.py", line 645, in send
    r = adapter.send(request, **kwargs)
  File "/usr/local/lib/python3.8/site-packages/requests/adapters.py", line 519, in send
    raise ConnectionError(e, request=request)
requests.exceptions.ConnectionError: HTTPConnectionPool(host='localhost', port=8000): Max retries exceeded with url: /api/v1/connections/sync (Caused by NewConnectionError('<urllib3.connection.HTTPConnection object at 0x7fc94a0947f0>: Failed to establish a new connection: [Errno 111] Connection refused'))
[2022-05-03 12:52:06,981] {taskinstance.py:1278} INFO - Marking task as FAILED. dag_id=trigger_airbyte_job_example, task_id=airbyte_example, execution_date=20220503T125204, start_date=20220503T125206, end_date=20220503T125206
[2022-05-03 12:52:06,986] {standard_task_runner.py:93} ERROR - Failed to execute job 3 for task airbyte_example (HTTPConnectionPool(host='localhost', port=8000): Max retries exceeded with url: /api/v1/connections/sync (Caused by NewConnectionError('<urllib3.connection.HTTPConnection object at 0x7fc94a0947f0>: Failed to establish a new connection: [Errno 111] Connection refused')); 1796)
[2022-05-03 12:52:06,996] {local_task_job.py:154} INFO - Task exited with return code 1
[2022-05-03 12:52:07,003] {local_task_job.py:264} INFO - 0 downstream tasks scheduled from follow-on schedule check
